Workbook

Sheet Lançamentos
A1: Data | B1: Descrição Extrato | C1: Categoria | D1: Tipo | E1: Grupo DRE | F1: Valor | G1: Banco | H1: Mês
A2: 01/06/2026 | B2: PIX CREDITO DE: POLLYANA ROCHA DA SILVA | C2: Vendas de Produtos | D2: =IF(C2="","",VLOOKUP(C2,Categorias!$A$2:$C$54,2,FALSE)) -> Entrada | E2: =IF(C2="","",VLOOKUP(C2,Categorias!$A$2:$C$54,3,FALSE)) -> Receita Bruta | F2: 16.99 | G2: Cresol | H2: =IF(A2="","",DATE(YEAR(A2),MONTH(A2),1)) -> 46174
A3: 01/06/2026 | B3: PIX CREDITO DE: LUCINEIA COSTA SARAIVA DE AM | C3: Vendas de Produtos | D3: =IF(C3="","",VLOOKUP(C3,Categorias!$A$2:$C$54,2,FALSE)) -> Entrada | E3: =IF(C3="","",VLOOKUP(C3,Categorias!$A$2:$C$54,3,FALSE)) -> Receita Bruta | F3: 25.98 | G3: Cresol | H3: =IF(A3="","",DATE(YEAR(A3),MONTH(A3),1)) -> 46174
A4: 01/06/2026 | B4: TED CRÉDITO 082 0000 07679404000100 BANCO | C4: Vendas de Produtos | D4: =IF(C4="","",VLOOKUP(C4,Categorias!$A$2:$C$54,2,FALSE)) -> Entrada | E4: =IF(C4="","",VLOOKUP(C4,Categorias!$A$2:$C$54,3,FALSE)) -> Receita Bruta | F4: 19.39 | G4: Cresol | H4: =IF(A4="","",DATE(YEAR(A4),MONTH(A4),1)) -> 46174
A5: 01/06/2026 | B5: PIX CREDITO DE: ANTONIO DONIZETI BIN - 31/05 | C5: Vendas de Produtos | D5: =IF(C5="","",VLOOKUP(C5,Categorias!$A$2:$C$54,2,FALSE)) -> Entrada | E5: =IF(C5="","",VLOOKUP(C5,Categorias!$A$2:$C$54,3,FALSE)) -> Receita Bruta | F5: 13.99 | G5: Cresol | H5: =IF(A5="","",DATE(YEAR(A5),MONTH(A5),1)) -> 46174
A6: 01/06/2026 | B6: PIX DEBITO INTERCOOPERATIVO PARA: CONDOMINIO RESIDENCIAL SPA | C6: Aluguel | D6: =IF(C6="","",VLOOKUP(C6,Categorias!$A$2:$C$54,2,FALSE)) -> Saída | E6: =IF(C6="","",VLOOKUP(C6,Categorias!$A$2:$C$54,3,FALSE)) -> Despesas Operacionais | F6: -1532.31 | G6: Cresol | H6: =IF(A6="","",DATE(YEAR(A6),MONTH(A6),1)) -> 46174
A7: 01/06/2026 | B7: PAGAMENTO DE TÍTULOS - IB SPAL IND BRAS DE BEBIDAS SA | C7: Pagamento de Fornecedores | D7: =IF(C7="","",VLOOKUP(C7,Categorias!$A$2:$C$54,2,FALSE)) -> Saída | E7: =IF(C7="","",VLOOKUP(C7,Categorias!$A$2:$C$54,3,FALSE)) -> CMV | F7: -709.94 | G7: Cresol | H7: =IF(A7="","",DATE(YEAR(A7),MONTH(A7),1)) -> 46174
A8: 01/06/2026 | B8: PAGAMENTO DE TÍTULOS - IB PENNACCHI CIA LTDA | C8: Pagamento de Fornecedores | D8: =IF(C8="","",VLOOKUP(C8,Categorias!$A$2:$C$54,2,FALSE)) -> Saída | E8: =IF(C8="","",VLOOKUP(C8,Categorias!$A$2:$C$54,3,FALSE)) -> CMV | F8: -1048.92 | G8: Cresol | H8: =IF(A8="","",DATE(YEAR(A8),MONTH(A8),1)) -> 46174
A9: 01/06/2026 | B9: PIX DEBITO PARA: WYLLAMY SANTOS DA SILVA | C9: Pagamento de Fornecedores | D9: =IF(C9="","",VLOOKUP(C9,Categorias!$A$2:$C$54,2,FALSE)) -> Saída | E9: =IF(C9="","",VLOOKUP(C9,Categorias!$A$2:$C$54,3,FALSE)) -> CMV | F9: -500 | G9: Cresol | H9: =IF(A9="","",DATE(YEAR(A9),MONTH(A9),1)) -> 46174
A10: 01/06/2026 | B10: CRÉDITO ANTECIPAÇÃO DE RECEBÍVEIS 10260001062611934-STONE -ELO | C10: Vendas de Produtos | D10: =IF(C10="","",VLOOKUP(C10,Categorias!$A$2:$C$54,2,FALSE)) -> Entrada | E10: =IF(C10="","",VLOOKUP(C10,Categorias!$A$2:$C$54,3,FALSE)) -> Receita Bruta | F10: 204.67 | G10: Cresol | H10: =IF(A10="","",DATE(YEAR(A10),MONTH(A10),1)) -> 46174
A11: 01/06/2026 | B11: CRÉDITO ANTECIPAÇÃO DE RECEBÍVEIS 10260001062611805-STONE -VISA | C11: Vendas de Produtos | D11: =IF(C11="","",VLOOKUP(C11,Categorias!$A$2:$C$54,2,FALSE)) -> Entrada | E11: =IF(C11="","",VLOOKUP(C11,Categorias!$A$2:$C$54,3,FALSE)) -> Receita Bruta | F11: 659.74 | G11: Cresol | H11: =IF(A11="","",DATE(YEAR(A11),MONTH(A11),1)) -> 46174
A12: 01/06/2026 | B12: CRÉDITO ANTECIPAÇÃO DE RECEBÍVEIS 10260001062611777-STONE -MASTERC | C12: Vendas de Produtos | D12: =IF(C12="","",VLOOKUP(C12,Categorias!$A$2:$C$54,2,FALSE)) -> Entrada | E12: =IF(C12="","",VLOOKUP(C12,Categorias!$A$2:$C$54,3,FALSE)) -> Receita Bruta | F12: 1472.8 | G12: Cresol | H12: =IF(A12="","",DATE(YEAR(A12),MONTH(A12),1)) -> 46174
A13: 01/06/2026 | B13: CRÉDITO ANTECIPAÇÃO DE RECEBÍVEIS 10260001062611738-STONE -AMERICA | C13: Vendas de Produtos | D13: =IF(C13="","",VLOOKUP(C13,Categorias!$A$2:$C$54,2,FALSE)) -> Entrada | E13: =IF(C13="","",VLOOKUP(C13,Categorias!$A$2:$C$54,3,FALSE)) -> Receita Bruta | F13: 57.67 | G13: Cresol | H13: =IF(A13="","",DATE(YEAR(A13),MONTH(A13),1)) -> 46174
... A349: 08/06/2026 | B349: RAMON LUIS BARZON DUARTE | 06835367962 | Pix | Maquininha | C349: Vendas de Produtos | D349: =IF(C349="","",VLOOKUP(C349,Categorias!$A$2:$C$54,2,FALSE)) -> Entrada | E349: =IF(C349="","",VLOOKUP(C349,Categorias!$A$2:$C$54,3,FALSE)) -> Receita Bruta | F349: 21.56 | G349: Stone | H349: =IF(A349="","",DATE(YEAR(A349),MONTH(A349),1)) -> 46174

Sheet Categorias
A1: Categoria | B1: Tipo | C1: Grupo DRE | E1: Banco | F1: Saldo Inicial
A2: Vendas de Produtos | B2: Entrada | C2: Receita Bruta | E2: Banco do Brasil | F2: 0
A3: Vendas de Serviços | B3: Entrada | C3: Receita Bruta | E3: Itaú | F3: 0
A4: Outras Receitas | B4: Entrada | C4: Outras Receitas | E4: Caixa | F4: 0
A5: Impostos sobre Vendas | B5: Saída | C5: Deduções | E5: Cresol
A6: Devoluções | B6: Saída | C6: Deduções | E6: Stone
A7: Custo de Mercadoria Vendida | B7: Saída | C7: CMV
A8: Custo de Serviços Prestados | B8: Saída | C8: CMV
A9: Salários e Encargos | B9: Saída | C9: Despesas Operacionais
A10: Aluguel | B10: Saída | C10: Despesas Operacionais
A11: Água, Luz e Internet | B11: Saída | C11: Despesas Operacionais
A12: Material de Escritório | B12: Saída | C12: Despesas Operacionais
A13: Marketing e Publicidade | B13: Saída | C13: Despesas Operacionais
A14: Manutenção | B14: Saída | C14: Despesas Operacionais
A15: Transporte e Viagens | B15: Saída | C15: Despesas Operacionais
A16: Serviços de Terceiros | B16: Saída | C16: Despesas Operacionais
A17: Juros e Tarifas Bancárias | B17: Saída | C17: Despesas Financeiras
A18: Empréstimos e Financiamentos | B18: Saída | C18: Despesas Financeiras
... A54: PIS/COFINS | B54: Saída | C54: Deduções

Sheet DRE
A1: DRE - Demonstração do Resultado
A3: Ano: | B3: =YEAR(TODAY()) -> 2026
A5: Grupo | B5: =DATE($B$3,1,1) -> 46023 | C5: =EDATE(B5,1) -> 46054 | D5: =EDATE(B5,2) -> 46082 | E5: =EDATE(B5,3) -> 46113 | F5: =EDATE(B5,4) -> 46143 | G5: =EDATE(B5,5) -> 46174 | H5: =EDATE(B5,6) -> 46204 | I5: =EDATE(B5,7) -> 46235 | J5: =EDATE(B5,8) -> 46266 | K5: =EDATE(B5,9) -> 46296 | L5: =EDATE(B5,10) -> 46327 | M5: =EDATE(B5,11) -> 46357 | N5: Total Ano
A6: (+) Receita Bruta | B6: =SUMIFS(Lançamentos!$F:$F,Lançamentos!$E:$E,"Receita Bruta",Lançamentos!$H:$H,B$5) -> 0 | C6: =SUMIFS(Lançamentos!$F:$F,Lançamentos!$E:$E,"Receita Bruta",Lançamentos!$H:$H,C$5) -> 0 | D6: =SUMIFS(Lançamentos!$F:$F,Lançamentos!$E:$E,"Receita Bruta",Lançamentos!$H:$H,D$5) -> 0 | E6: =SUMIFS(Lançamentos!$F:$F,Lançamentos!$E:$E,"Receita Bruta",Lançamentos!$H:$H,E$5) -> 0 | F6: =SUMIFS(Lançamentos!$F:$F,Lançamentos!$E:$E,"Receita Bruta",Lançamentos!$H:$H,F$5) -> 0 | G6: =SUMIFS(Lançamentos!$F:$F,Lançamentos!$E:$E,"Receita Bruta",Lançamentos!$H:$H,G$5) -> 20878.13 | H6: =SUMIFS(Lançamentos!$F:$F,Lançamentos!$E:$E,"Receita Bruta",Lançamentos!$H:$H,H$5) -> 0 | I6: =SUMIFS(Lançamentos!$F:$F,Lançamentos!$E:$E,"Receita Bruta",Lançamentos!$H:$H,I$5) -> 0 | ... M6: =SUMIFS(Lançamentos!$F:$F,Lançamentos!$E:$E,"Receita Bruta",Lançamentos!$H:$H,M$5) -> 0 | N6: =SUM(B6:M6) -> 20878.13
A7: (-) Deduções | B7: =SUMIFS(Lançamentos!$F:$F,Lançamentos!$E:$E,"Deduções",Lançamentos!$H:$H,B$5) -> 0 | C7: =SUMIFS(Lançamentos!$F:$F,Lançamentos!$E:$E,"Deduções",Lançamentos!$H:$H,C$5) -> 0 | D7: =SUMIFS(Lançamentos!$F:$F,Lançamentos!$E:$E,"Deduções",Lançamentos!$H:$H,D$5) -> 0 | E7: =SUMIFS(Lançamentos!$F:$F,Lançamentos!$E:$E,"Deduções",Lançamentos!$H:$H,E$5) -> 0 | F7: =SUMIFS(Lançamentos!$F:$F,Lançamentos!$E:$E,"Deduções",Lançamentos!$H:$H,F$5) -> 0 | G7: =SUMIFS(Lançamentos!$F:$F,Lançamentos!$E:$E,"Deduções",Lançamentos!$H:$H,G$5) -> 0 | H7: =SUMIFS(Lançamentos!$F:$F,Lançamentos!$E:$E,"Deduções",Lançamentos!$H:$H,H$5) -> 0 | I7: =SUMIFS(Lançamentos!$F:$F,Lançamentos!$E:$E,"Deduções",Lançamentos!$H:$H,I$5) -> 0 | ... M7: =SUMIFS(Lançamentos!$F:$F,Lançamentos!$E:$E,"Deduções",Lançamentos!$H:$H,M$5) -> 0 | N7: =SUM(B7:M7) -> 0
A8: (=) Receita Líquida | B8: =B6+B7 -> 0 | C8: =C6+C7 -> 0 | D8: =D6+D7 -> 0 | E8: =E6+E7 -> 0 | F8: =F6+F7 -> 0 | G8: =G6+G7 -> 20878.13 | H8: =H6+H7 -> 0 | I8: =I6+I7 -> 0 | ... M8: =M6+M7 -> 0 | N8: =SUM(B8:M8) -> 20878.13
A9: (-) CMV | B9: =SUMIFS(Lançamentos!$F:$F,Lançamentos!$E:$E,"CMV",Lançamentos!$H:$H,B$5) -> 0 | C9: =SUMIFS(Lançamentos!$F:$F,Lançamentos!$E:$E,"CMV",Lançamentos!$H:$H,C$5) -> 0 | D9: =SUMIFS(Lançamentos!$F:$F,Lançamentos!$E:$E,"CMV",Lançamentos!$H:$H,D$5) -> 0 | E9: =SUMIFS(Lançamentos!$F:$F,Lançamentos!$E:$E,"CMV",Lançamentos!$H:$H,E$5) -> 0 | F9: =SUMIFS(Lançamentos!$F:$F,Lançamentos!$E:$E,"CMV",Lançamentos!$H:$H,F$5) -> 0 | G9: =SUMIFS(Lançamentos!$F:$F,Lançamentos!$E:$E,"CMV",Lançamentos!$H:$H,G$5) -> -14865.69 | H9: =SUMIFS(Lançamentos!$F:$F,Lançamentos!$E:$E,"CMV",Lançamentos!$H:$H,H$5) -> 0 | I9: =SUMIFS(Lançamentos!$F:$F,Lançamentos!$E:$E,"CMV",Lançamentos!$H:$H,I$5) -> 0 | ... M9: =SUMIFS(Lançamentos!$F:$F,Lançamentos!$E:$E,"CMV",Lançamentos!$H:$H,M$5) -> 0 | N9: =SUM(B9:M9) -> -14865.69
A10: (=) Lucro Bruto | B10: =B8+B9 -> 0 | C10: =C8+C9 -> 0 | D10: =D8+D9 -> 0 | E10: =E8+E9 -> 0 | F10: =F8+F9 -> 0 | G10: =G8+G9 -> 6012.44 | H10: =H8+H9 -> 0 | I10: =I8+I9 -> 0 | ... M10: =M8+M9 -> 0 | N10: =SUM(B10:M10) -> 6012.44
A11: (-) Despesas Operacionais | B11: =SUMIFS(Lançamentos!$F:$F,Lançamentos!$E:$E,"Despesas Operacionais",Lançamentos!$H:$H,B$5) -> 0 | C11: =SUMIFS(Lançamentos!$F:$F,Lançamentos!$E:$E,"Despesas Operacionais",Lançamentos!$H:$H,C$5) -> 0 | D11: =SUMIFS(Lançamentos!$F:$F,Lançamentos!$E:$E,"Despesas Operacionais",Lançamentos!$H:$H,D$5) -> 0 | E11: =SUMIFS(Lançamentos!$F:$F,Lançamentos!$E:$E,"Despesas Operacionais",Lançamentos!$H:$H,E$5) -> 0 | F11: =SUMIFS(Lançamentos!$F:$F,Lançamentos!$E:$E,"Despesas Operacionais",Lançamentos!$H:$H,F$5) -> 0 | G11: =SUMIFS(Lançamentos!$F:$F,Lançamentos!$E:$E,"Despesas Operacionais",Lançamentos!$H:$H,G$5) -> -2831.08 | H11: =SUMIFS(Lançamentos!$F:$F,Lançamentos!$E:$E,"Despesas Operacionais",Lançamentos!$H:$H,H$5) -> 0 | I11: =SUMIFS(Lançamentos!$F:$F,Lançamentos!$E:$E,"Despesas Operacionais",Lançamentos!$H:$H,I$5) -> 0 | ... M11: =SUMIFS(Lançamentos!$F:$F,Lançamentos!$E:$E,"Despesas Operacionais",Lançamentos!$H:$H,M$5) -> 0 | N11: =SUM(B11:M11) -> -2831.08
A12: (=) EBITDA | B12: =B10+B11 -> 0 | C12: =C10+C11 -> 0 | D12: =D10+D11 -> 0 | E12: =E10+E11 -> 0 | F12: =F10+F11 -> 0 | G12: =G10+G11 -> 3181.36 | H12: =H10+H11 -> 0 | I12: =I10+I11 -> 0 | ... M12: =M10+M11 -> 0 | N12: =SUM(B12:M12) -> 3181.36
A13: (+) Receitas Financeiras | B13: =SUMIFS(Lançamentos!$F:$F,Lançamentos!$E:$E,"Receitas Financeiras",Lançamentos!$H:$H,B$5) -> 0 | C13: =SUMIFS(Lançamentos!$F:$F,Lançamentos!$E:$E,"Receitas Financeiras",Lançamentos!$H:$H,C$5) -> 0 | D13: =SUMIFS(Lançamentos!$F:$F,Lançamentos!$E:$E,"Receitas Financeiras",Lançamentos!$H:$H,D$5) -> 0 | E13: =SUMIFS(Lançamentos!$F:$F,Lançamentos!$E:$E,"Receitas Financeiras",Lançamentos!$H:$H,E$5) -> 0 | F13: =SUMIFS(Lançamentos!$F:$F,Lançamentos!$E:$E,"Receitas Financeiras",Lançamentos!$H:$H,F$5) -> 0 | G13: =SUMIFS(Lançamentos!$F:$F,Lançamentos!$E:$E,"Receitas Financeiras",Lançamentos!$H:$H,G$5) -> 0 | H13: =SUMIFS(Lançamentos!$F:$F,Lançamentos!$E:$E,"Receitas Financeiras",Lançamentos!$H:$H,H$5) -> 0 | I13: =SUMIFS(Lançamentos!$F:$F,Lançamentos!$E:$E,"Receitas Financeiras",Lançamentos!$H:$H,I$5) -> 0 | ... M13: =SUMIFS(Lançamentos!$F:$F,Lançamentos!$E:$E,"Receitas Financeiras",Lançamentos!$H:$H,M$5) -> 0 | N13: =SUM(B13:M13) -> 0
A14: (-) Despesas Financeiras | B14: =SUMIFS(Lançamentos!$F:$F,Lançamentos!$E:$E,"Despesas Financeiras",Lançamentos!$H:$H,B$5) -> 0 | C14: =SUMIFS(Lançamentos!$F:$F,Lançamentos!$E:$E,"Despesas Financeiras",Lançamentos!$H:$H,C$5) -> 0 | D14: =SUMIFS(Lançamentos!$F:$F,Lançamentos!$E:$E,"Despesas Financeiras",Lançamentos!$H:$H,D$5) -> 0 | E14: =SUMIFS(Lançamentos!$F:$F,Lançamentos!$E:$E,"Despesas Financeiras",Lançamentos!$H:$H,E$5) -> 0 | F14: =SUMIFS(Lançamentos!$F:$F,Lançamentos!$E:$E,"Despesas Financeiras",Lançamentos!$H:$H,F$5) -> 0 | G14: =SUMIFS(Lançamentos!$F:$F,Lançamentos!$E:$E,"Despesas Financeiras",Lançamentos!$H:$H,G$5) -> -14.57 | H14: =SUMIFS(Lançamentos!$F:$F,Lançamentos!$E:$E,"Despesas Financeiras",Lançamentos!$H:$H,H$5) -> 0 | I14: =SUMIFS(Lançamentos!$F:$F,Lançamentos!$E:$E,"Despesas Financeiras",Lançamentos!$H:$H,I$5) -> 0 | ... M14: =SUMIFS(Lançamentos!$F:$F,Lançamentos!$E:$E,"Despesas Financeiras",Lançamentos!$H:$H,M$5) -> 0 | N14: =SUM(B14:M14) -> -14.57
A15: (+) Outras Receitas | B15: =SUMIFS(Lançamentos!$F:$F,Lançamentos!$E:$E,"Outras Receitas",Lançamentos!$H:$H,B$5) -> 0 | C15: =SUMIFS(Lançamentos!$F:$F,Lançamentos!$E:$E,"Outras Receitas",Lançamentos!$H:$H,C$5) -> 0 | D15: =SUMIFS(Lançamentos!$F:$F,Lançamentos!$E:$E,"Outras Receitas",Lançamentos!$H:$H,D$5) -> 0 | E15: =SUMIFS(Lançamentos!$F:$F,Lançamentos!$E:$E,"Outras Receitas",Lançamentos!$H:$H,E$5) -> 0 | F15: =SUMIFS(Lançamentos!$F:$F,Lançamentos!$E:$E,"Outras Receitas",Lançamentos!$H:$H,F$5) -> 0 | G15: =SUMIFS(Lançamentos!$F:$F,Lançamentos!$E:$E,"Outras Receitas",Lançamentos!$H:$H,G$5) -> 0 | H15: =SUMIFS(Lançamentos!$F:$F,Lançamentos!$E:$E,"Outras Receitas",Lançamentos!$H:$H,H$5) -> 0 | I15: =SUMIFS(Lançamentos!$F:$F,Lançamentos!$E:$E,"Outras Receitas",Lançamentos!$H:$H,I$5) -> 0 | ... M15: =SUMIFS(Lançamentos!$F:$F,Lançamentos!$E:$E,"Outras Receitas",Lançamentos!$H:$H,M$5) -> 0 | N15: =SUM(B15:M15) -> 0
A16: (=) Resultado antes dos Impostos | B16: =B12+B13+B14+B15 -> 0 | C16: =C12+C13+C14+C15 -> 0 | D16: =D12+D13+D14+D15 -> 0 | E16: =E12+E13+E14+E15 -> 0 | F16: =F12+F13+F14+F15 -> 0 | G16: =G12+G13+G14+G15 -> 3166.79 | H16: =H12+H13+H14+H15 -> 0 | I16: =I12+I13+I14+I15 -> 0 | ... M16: =M12+M13+M14+M15 -> 0 | N16: =SUM(B16:M16) -> 3166.79
A17: (-) Impostos sobre Lucro | B17: =SUMIFS(Lançamentos!$F:$F,Lançamentos!$E:$E,"Impostos",Lançamentos!$H:$H,B$5) -> 0 | C17: =SUMIFS(Lançamentos!$F:$F,Lançamentos!$E:$E,"Impostos",Lançamentos!$H:$H,C$5) -> 0 | D17: =SUMIFS(Lançamentos!$F:$F,Lançamentos!$E:$E,"Impostos",Lançamentos!$H:$H,D$5) -> 0 | E17: =SUMIFS(Lançamentos!$F:$F,Lançamentos!$E:$E,"Impostos",Lançamentos!$H:$H,E$5) -> 0 | F17: =SUMIFS(Lançamentos!$F:$F,Lançamentos!$E:$E,"Impostos",Lançamentos!$H:$H,F$5) -> 0 | G17: =SUMIFS(Lançamentos!$F:$F,Lançamentos!$E:$E,"Impostos",Lançamentos!$H:$H,G$5) -> 0 | H17: =SUMIFS(Lançamentos!$F:$F,Lançamentos!$E:$E,"Impostos",Lançamentos!$H:$H,H$5) -> 0 | I17: =SUMIFS(Lançamentos!$F:$F,Lançamentos!$E:$E,"Impostos",Lançamentos!$H:$H,I$5) -> 0 | ... M17: =SUMIFS(Lançamentos!$F:$F,Lançamentos!$E:$E,"Impostos",Lançamentos!$H:$H,M$5) -> 0 | N17: =SUM(B17:M17) -> 0
A18: (=) LUCRO LÍQUIDO | B18: =B16+B17 -> 0 | C18: =C16+C17 -> 0 | D18: =D16+D17 -> 0 | E18: =E16+E17 -> 0 | F18: =F16+F17 -> 0 | G18: =G16+G17 -> 3166.79 | H18: =H16+H17 -> 0 | I18: =I16+I17 -> 0 | ... M18: =M16+M17 -> 0 | N18: =SUM(B18:M18) -> 3166.79

Sheet Fluxo de Caixa
A1: Fluxo de Caixa
A3: Ano: | B3: =DRE!B3 -> 2026
A5: Item | B5: =DATE($B$3,1,1) -> 46023 | C5: =EDATE(B5,1) -> 46054 | D5: =EDATE(B5,2) -> 46082 | E5: =EDATE(B5,3) -> 46113 | F5: =EDATE(B5,4) -> 46143 | G5: =EDATE(B5,5) -> 46174 | H5: =EDATE(B5,6) -> 46204 | I5: =EDATE(B5,7) -> 46235 | J5: =EDATE(B5,8) -> 46266 | K5: =EDATE(B5,9) -> 46296 | L5: =EDATE(B5,10) -> 46327 | M5: =EDATE(B5,11) -> 46357 | N5: Total
A6: Saldo Inicial | B6: =SUM(Categorias!F2:F4) -> 0 | C6: =B10 -> 0 | D6: =C10 -> 0 | E6: =D10 -> 0 | F6: =E10 -> 0 | G6: =F10 -> 0 | H6: =G10 -> 3166.79 | I6: =H10 -> 3166.79 | J6: =I10 -> 3166.79 | ... M6: =L10 -> 3166.79
A7: (+) Total de Entradas | B7: =SUMIFS(Lançamentos!$F:$F,Lançamentos!$H:$H,B$5,Lançamentos!$D:$D,"Entrada") -> 0 | C7: =SUMIFS(Lançamentos!$F:$F,Lançamentos!$H:$H,C$5,Lançamentos!$D:$D,"Entrada") -> 0 | D7: =SUMIFS(Lançamentos!$F:$F,Lançamentos!$H:$H,D$5,Lançamentos!$D:$D,"Entrada") -> 0 | E7: =SUMIFS(Lançamentos!$F:$F,Lançamentos!$H:$H,E$5,Lançamentos!$D:$D,"Entrada") -> 0 | F7: =SUMIFS(Lançamentos!$F:$F,Lançamentos!$H:$H,F$5,Lançamentos!$D:$D,"Entrada") -> 0 | G7: =SUMIFS(Lançamentos!$F:$F,Lançamentos!$H:$H,G$5,Lançamentos!$D:$D,"Entrada") -> 20878.13 | H7: =SUMIFS(Lançamentos!$F:$F,Lançamentos!$H:$H,H$5,Lançamentos!$D:$D,"Entrada") -> 0 | I7: =SUMIFS(Lançamentos!$F:$F,Lançamentos!$H:$H,I$5,Lançamentos!$D:$D,"Entrada") -> 0 | ... M7: =SUMIFS(Lançamentos!$F:$F,Lançamentos!$H:$H,M$5,Lançamentos!$D:$D,"Entrada") -> 0 | N7: =SUM(B7:M7) -> 20878.13
A8: (-) Total de Saídas | B8: =SUMIFS(Lançamentos!$F:$F,Lançamentos!$H:$H,B$5,Lançamentos!$D:$D,"Saída") -> 0 | C8: =SUMIFS(Lançamentos!$F:$F,Lançamentos!$H:$H,C$5,Lançamentos!$D:$D,"Saída") -> 0 | D8: =SUMIFS(Lançamentos!$F:$F,Lançamentos!$H:$H,D$5,Lançamentos!$D:$D,"Saída") -> 0 | E8: =SUMIFS(Lançamentos!$F:$F,Lançamentos!$H:$H,E$5,Lançamentos!$D:$D,"Saída") -> 0 | F8: =SUMIFS(Lançamentos!$F:$F,Lançamentos!$H:$H,F$5,Lançamentos!$D:$D,"Saída") -> 0 | G8: =SUMIFS(Lançamentos!$F:$F,Lançamentos!$H:$H,G$5,Lançamentos!$D:$D,"Saída") -> -17711.34 | H8: =SUMIFS(Lançamentos!$F:$F,Lançamentos!$H:$H,H$5,Lançamentos!$D:$D,"Saída") -> 0 | I8: =SUMIFS(Lançamentos!$F:$F,Lançamentos!$H:$H,I$5,Lançamentos!$D:$D,"Saída") -> 0 | ... M8: =SUMIFS(Lançamentos!$F:$F,Lançamentos!$H:$H,M$5,Lançamentos!$D:$D,"Saída") -> 0 | N8: =SUM(B8:M8) -> -17711.34
A9: (=) Fluxo do Mês | B9: =B7+B8 -> 0 | C9: =C7+C8 -> 0 | D9: =D7+D8 -> 0 | E9: =E7+E8 -> 0 | F9: =F7+F8 -> 0 | G9: =G7+G8 -> 3166.79 | H9: =H7+H8 -> 0 | I9: =I7+I8 -> 0 | ... M9: =M7+M8 -> 0 | N9: =SUM(B9:M9) -> 3166.79
A10: (=) Saldo Acumulado | B10: =B6+B9 -> 0 | C10: =C6+C9 -> 0 | D10: =D6+D9 -> 0 | E10: =E6+E9 -> 0 | F10: =F6+F9 -> 0 | G10: =G6+G9 -> 3166.79 | H10: =H6+H9 -> 3166.79 | I10: =I6+I9 -> 3166.79 | ... M10: =M6+M9 -> 3166.79 | N10: =M10 -> 3166.79
A12: Detalhamento por Banco
A13: =Categorias!E2 -> Banco do Brasil | B13: =Categorias!F2+SUMIFS(Lançamentos!$F:$F,Lançamentos!$G:$G,$A13,Lançamentos!$H:$H,B$5) -> 0 | C13: =Categorias!G2+SUMIFS(Lançamentos!$F:$F,Lançamentos!$G:$G,$A13,Lançamentos!$H:$H,C$5) -> 0 | D13: =Categorias!H2+SUMIFS(Lançamentos!$F:$F,Lançamentos!$G:$G,$A13,Lançamentos!$H:$H,D$5) -> 0 | E13: =Categorias!I2+SUMIFS(Lançamentos!$F:$F,Lançamentos!$G:$G,$A13,Lançamentos!$H:$H,E$5) -> 0 | F13: =Categorias!J2+SUMIFS(Lançamentos!$F:$F,Lançamentos!$G:$G,$A13,Lançamentos!$H:$H,F$5) -> 0 | G13: =Categorias!K2+SUMIFS(Lançamentos!$F:$F,Lançamentos!$G:$G,$A13,Lançamentos!$H:$H,G$5) -> 0 | H13: =Categorias!L2+SUMIFS(Lançamentos!$F:$F,Lançamentos!$G:$G,$A13,Lançamentos!$H:$H,H$5) -> 0 | I13: =Categorias!M2+SUMIFS(Lançamentos!$F:$F,Lançamentos!$G:$G,$A13,Lançamentos!$H:$H,I$5) -> 0 | ... M13: =Categorias!Q2+SUMIFS(Lançamentos!$F:$F,Lançamentos!$G:$G,$A13,Lançamentos!$H:$H,M$5) -> 0 | N13: =M13 -> 0
A14: =Categorias!E3 -> Itaú | B14: =Categorias!F3+SUMIFS(Lançamentos!$F:$F,Lançamentos!$G:$G,$A14,Lançamentos!$H:$H,B$5) -> 0 | C14: =Categorias!G3+SUMIFS(Lançamentos!$F:$F,Lançamentos!$G:$G,$A14,Lançamentos!$H:$H,C$5) -> 0 | D14: =Categorias!H3+SUMIFS(Lançamentos!$F:$F,Lançamentos!$G:$G,$A14,Lançamentos!$H:$H,D$5) -> 0 | E14: =Categorias!I3+SUMIFS(Lançamentos!$F:$F,Lançamentos!$G:$G,$A14,Lançamentos!$H:$H,E$5) -> 0 | F14: =Categorias!J3+SUMIFS(Lançamentos!$F:$F,Lançamentos!$G:$G,$A14,Lançamentos!$H:$H,F$5) -> 0 | G14: =Categorias!K3+SUMIFS(Lançamentos!$F:$F,Lançamentos!$G:$G,$A14,Lançamentos!$H:$H,G$5) -> 0 | H14: =Categorias!L3+SUMIFS(Lançamentos!$F:$F,Lançamentos!$G:$G,$A14,Lançamentos!$H:$H,H$5) -> 0 | I14: =Categorias!M3+SUMIFS(Lançamentos!$F:$F,Lançamentos!$G:$G,$A14,Lançamentos!$H:$H,I$5) -> 0 | ... M14: =Categorias!Q3+SUMIFS(Lançamentos!$F:$F,Lançamentos!$G:$G,$A14,Lançamentos!$H:$H,M$5) -> 0 | N14: =M14 -> 0
A15: =Categorias!E4 -> Caixa | B15: =Categorias!F4+SUMIFS(Lançamentos!$F:$F,Lançamentos!$G:$G,$A15,Lançamentos!$H:$H,B$5) -> 0 | C15: =Categorias!G4+SUMIFS(Lançamentos!$F:$F,Lançamentos!$G:$G,$A15,Lançamentos!$H:$H,C$5) -> 0 | D15: =Categorias!H4+SUMIFS(Lançamentos!$F:$F,Lançamentos!$G:$G,$A15,Lançamentos!$H:$H,D$5) -> 0 | E15: =Categorias!I4+SUMIFS(Lançamentos!$F:$F,Lançamentos!$G:$G,$A15,Lançamentos!$H:$H,E$5) -> 0 | F15: =Categorias!J4+SUMIFS(Lançamentos!$F:$F,Lançamentos!$G:$G,$A15,Lançamentos!$H:$H,F$5) -> 0 | G15: =Categorias!K4+SUMIFS(Lançamentos!$F:$F,Lançamentos!$G:$G,$A15,Lançamentos!$H:$H,G$5) -> 0 | H15: =Categorias!L4+SUMIFS(Lançamentos!$F:$F,Lançamentos!$G:$G,$A15,Lançamentos!$H:$H,H$5) -> 0 | I15: =Categorias!M4+SUMIFS(Lançamentos!$F:$F,Lançamentos!$G:$G,$A15,Lançamentos!$H:$H,I$5) -> 0 | ... M15: =Categorias!Q4+SUMIFS(Lançamentos!$F:$F,Lançamentos!$G:$G,$A15,Lançamentos!$H:$H,M$5) -> 0 | N15: =M15 -> 0
A18: FLUXO DE CAIXA DIÁRIO (Mai-Dez)
A19: Data → | B19: =DATE(2026,5,1) -> 46143 | C19: =DATE(2026,5,2) -> 46144 | D19: =DATE(2026,5,3) -> 46145 | E19: =DATE(2026,5,4) -> 46146 | F19: =DATE(2026,5,5) -> 46147 | G19: =DATE(2026,5,6) -> 46148 | H19: =DATE(2026,5,7) -> 46149 | I19: =DATE(2026,5,8) -> 46150 | J19: =DATE(2026,5,9) -> 46151 | K19: =DATE(2026,5,10) -> 46152 | L19: =DATE(2026,5,11) -> 46153 | M19: =DATE(2026,5,12) -> 46154 | N19: =DATE(2026,5,13) -> 46155 | O19: =DATE(2026,5,14) -> 46156 | P19: =DATE(2026,5,15) -> 46157 | Q19: =DATE(2026,5,16) -> 46158 | R19: =DATE(2026,5,17) -> 46159 | S19: =DATE(2026,5,18) -> 46160 | T19: =DATE(2026,5,19) -> 46161 | U19: =DATE(2026,5,20) -> 46162 | V19: =DATE(2026,5,21) -> 46163 | W19: =DATE(2026,5,22) -> 46164 | X19: =DATE(2026,5,23) -> 46165 | Y19: =DATE(2026,5,24) -> 46166 | Z19: =DATE(2026,5,25) -> 46167 | AA19: =DATE(2026,5,26) -> 46168 | AB19: =DATE(2026,5,27) -> 46169 | AC19: =DATE(2026,5,28) -> 46170 | AD19: =DATE(2026,5,29) -> 46171 | AE19: =DATE(2026,5,30) -> 46172 | AF19: =DATE(2026,5,31) -> 46173 | AG19: =DATE(2026,6,1) -> 46174 | AH19: =DATE(2026,6,2) -> 46175 | AI19: =DATE(2026,6,3) -> 46176 | AJ19: =DATE(2026,6,4) -> 46177 | AK19: =DATE(2026,6,5) -> 46178 | AL19: =DATE(2026,6,6) -> 46179 | AM19: =DATE(2026,6,7) -> 46180 | AN19: =DATE(2026,6,8) -> 46181 | AO19: =DATE(2026,6,9) -> 46182 | AP19: =DATE(2026,6,10) -> 46183 | AQ19: =DATE(2026,6,11) -> 46184 | AR19: =DATE(2026,6,12) -> 46185 | AS19: =DATE(2026,6,13) -> 46186 | AT19: =DATE(2026,6,14) -> 46187 | AU19: =DATE(2026,6,15) -> 46188 | AV19: =DATE(2026,6,16) -> 46189 | AW19: =DATE(2026,6,17) -> 46190 | AX19: =DATE(2026,6,18) -> 46191 | AY19: =DATE(2026,6,19) -> 46192 | AZ19: =DATE(2026,6,20) -> 46193 | BA19: =DATE(2026,6,21) -> 46194 | BB19: =DATE(2026,6,22) -> 46195 | BC19: =DATE(2026,6,23) -> 46196 | BD19: =DATE(2026,6,24) -> 46197 | BE19: =DATE(2026,6,25) -> 46198 | BF19: =DATE(2026,6,26) -> 46199 | BG19: =DATE(2026,6,27) -> 46200 | BH19: =DATE(2026,6,28) -> 46201 | BI19: =DATE(2026,6,29) -> 46202 | BJ19: =DATE(2026,6,30) -> 46203 | BK19: =DATE(2026,7,1) -> 46204 | BL19: =DATE(2026,7,2) -> 46205 | BM19: =DATE(2026,7,3) -> 46206 | BN19: =DATE(2026,7,4) -> 46207 | BO19: =DATE(2026,7,5) -> 46208 | BP19: =DATE(2026,7,6) -> 46209 | BQ19: =DATE(2026,7,7) -> 46210 | BR19: =DATE(2026,7,8) -> 46211 | BS19: =DATE(2026,7,9) -> 46212 | BT19: =DATE(2026,7,10) -> 46213 | BU19: =DATE(2026,7,11) -> 46214 | BV19: =DATE(2026,7,12) -> 46215 | BW19: =DATE(2026,7,13) -> 46216 | BX19: =DATE(2026,7,14) -> 46217 | BY19: =DATE(2026,7,15) -> 46218 | BZ19: =DATE(2026,7,16) -> 46219 | CA19: =DATE(2026,7,17) -> 46220 | CB19: =DATE(2026,7,18) -> 46221 | CC19: =DATE(2026,7,19) -> 46222 | CD19: =DATE(2026,7,20) -> 46223 | CE19: =DATE(2026,7,21) -> 46224 | CF19: =DATE(2026,7,22) -> 46225 | CG19: =DATE(2026,7,23) -> 46226 | CH19: =DATE(2026,7,24) -> 46227 | CI19: =DATE(2026,7,25) -> 46228 | CJ19: =DATE(2026,7,26) -> 46229 | CK19: =DATE(2026,7,27) -> 46230 | CL19: =DATE(2026,7,28) -> 46231 | CM19: =DATE(2026,7,29) -> 46232 | CN19: =DATE(2026,7,30) -> 46233 | CO19: =DATE(2026,7,31) -> 46234 | CP19: =DATE(2026,8,1) -> 46235 | CQ19: =DATE(2026,8,2) -> 46236 | CR19: =DATE(2026,8,3) -> 46237 | CS19: =DATE(2026,8,4) -> 46238 | CT19: =DATE(2026,8,5) -> 46239 | CU19: =DATE(2026,8,6) -> 46240 | CV19: =DATE(2026,8,7) -> 46241 | CW19: =DATE(2026,8,8) -> 46242 | CX19: =DATE(2026,8,9) -> 46243 | CY19: =DATE(2026,8,10) -> 46244 | CZ19: =DATE(2026,8,11) -> 46245 | DA19: =DATE(2026,8,12) -> 46246 | DB19: =DATE(2026,8,13) -> 46247 | DC19: =DATE(2026,8,14) -> 46248 | DD19: =DATE(2026,8,15) -> 46249 | DE19: =DATE(2026,8,16) -> 46250 | DF19: =DATE(2026,8,17) -> 46251 | DG19: =DATE(2026,8,18) -> 46252 | DH19: =DATE(2026,8,19) -> 46253 | DI19: =DATE(2026,8,20) -> 46254 | DJ19: =DATE(2026,8,21) -> 46255 | DK19: =DATE(2026,8,22) -> 46256 | DL19: =DATE(2026,8,23) -> 46257 | DM19: =DATE(2026,8,24) -> 46258 | DN19: =DATE(2026,8,25) -> 46259 | DO19: =DATE(2026,8,26) -> 46260 | DP19: =DATE(2026,8,27) -> 46261 | DQ19: =DATE(2026,8,28) -> 46262 | DR19: =DATE(2026,8,29) -> 46263 | DS19: =DATE(2026,8,30) -> 46264 | DT19: =DATE(2026,8,31) -> 46265 | DU19: =DATE(2026,9,1) -> 46266 | DV19: =DATE(2026,9,2) -> 46267 | DW19: =DATE(2026,9,3) -> 46268 | DX19: =DATE(2026,9,4) -> 46269 | DY19: =DATE(2026,9,5) -> 46270 | DZ19: =DATE(2026,9,6) -> 46271 | EA19: =DATE(2026,9,7) -> 46272 | EB19: =DATE(2026,9,8) -> 46273 | EC19: =DATE(2026,9,9) -> 46274 | ED19: =DATE(2026,9,10) -> 46275 | EE19: =DATE(2026,9,11) -> 46276 | EF19: =DATE(2026,9,12) -> 46277 | EG19: =DATE(2026,9,13) -> 46278 | EH19: =DATE(2026,9,14) -> 46279 | EI19: =DATE(2026,9,15) -> 46280 | EJ19: =DATE(2026,9,16) -> 46281 | EK19: =DATE(2026,9,17) -> 46282 | EL19: =DATE(2026,9,18) -> 46283 | EM19: =DATE(2026,9,19) -> 46284 | EN19: =DATE(2026,9,20) -> 46285 | EO19: =DATE(2026,9,21) -> 46286 | EP19: =DATE(2026,9,22) -> 46287 | EQ19: =DATE(2026,9,23) -> 46288 | ER19: =DATE(2026,9,24) -> 46289 | ES19: =DATE(2026,9,25) -> 46290 | ET19: =DATE(2026,9,26) -> 46291 | EU19: =DATE(2026,9,27) -> 46292 | EV19: =DATE(2026,9,28) -> 46293 | EW19: =DATE(2026,9,29) -> 46294 | EX19: =DATE(2026,9,30) -> 46295 | EY19: =DATE(2026,10,1) -> 46296 | EZ19: =DATE(2026,10,2) -> 46297 | FA19: =DATE(2026,10,3) -> 46298 | FB19: =DATE(2026,10,4) -> 46299 | FC19: =DATE(2026,10,5) -> 46300 | FD19: =DATE(2026,10,6) -> 46301 | FE19: =DATE(2026,10,7) -> 46302 | FF19: =DATE(2026,10,8) -> 46303 | FG19: =DATE(2026,10,9) -> 46304 | FH19: =DATE(2026,10,10) -> 46305 | FI19: =DATE(2026,10,11) -> 46306 | FJ19: =DATE(2026,10,12) -> 46307 | FK19: =DATE(2026,10,13) -> 46308 | FL19: =DATE(2026,10,14) -> 46309 | FM19: =DATE(2026,10,15) -> 46310 | FN19: =DATE(2026,10,16) -> 46311 | FO19: =DATE(2026,10,17) -> 46312 | FP19: =DATE(2026,10,18) -> 46313 | FQ19: =DATE(2026,10,19) -> 46314 | FR19: =DATE(2026,10,20) -> 46315 | FS19: =DATE(2026,10,21) -> 46316 | FT19: =DATE(2026,10,22) -> 46317 | FU19: =DATE(2026,10,23) -> 46318 | FV19: =DATE(2026,10,24) -> 46319 | FW19: =DATE(2026,10,25) -> 46320 | FX19: =DATE(2026,10,26) -> 46321 | FY19: =DATE(2026,10,27) -> 46322 | FZ19: =DATE(2026,10,28) -> 46323 | GA19: =DATE(2026,10,29) -> 46324 | GB19: =DATE(2026,10,30) -> 46325 | GC19: =DATE(2026,10,31) -> 46326 | GD19: =DATE(2026,11,1) -> 46327 | GE19: =DATE(2026,11,2) -> 46328 | GF19: =DATE(2026,11,3) -> 46329 | GG19: =DATE(2026,11,4) -> 46330 | GH19: =DATE(2026,11,5) -> 46331 | GI19: =DATE(2026,11,6) -> 46332 | GJ19: =DATE(2026,11,7) -> 46333 | GK19: =DATE(2026,11,8) -> 46334 | GL19: =DATE(2026,11,9) -> 46335 | GM19: =DATE(2026,11,10) -> 46336 | GN19: =DATE(2026,11,11) -> 46337 | GO19: =DATE(2026,11,12) -> 46338 | GP19: =DATE(2026,11,13) -> 46339 | GQ19: =DATE(2026,11,14) -> 46340 | GR19: =DATE(2026,11,15) -> 46341 | GS19: =DATE(2026,11,16) -> 46342 | GT19: =DATE(2026,11,17) -> 46343 | GU19: =DATE(2026,11,18) -> 46344 | GV19: =DATE(2026,11,19) -> 46345 | GW19: =DATE(2026,11,20) -> 46346 | GX19: =DATE(2026,11,21) -> 46347 | GY19: =DATE(2026,11,22) -> 46348 | GZ19: =DATE(2026,11,23) -> 46349 | HA19: =DATE(2026,11,24) -> 46350 | HB19: =DATE(2026,11,25) -> 46351 | HC19: =DATE(2026,11,26) -> 46352 | HD19: =DATE(2026,11,27) -> 46353 | HE19: =DATE(2026,11,28) -> 46354 | HF19: =DATE(2026,11,29) -> 46355 | HG19: =DATE(2026,11,30) -> 46356 | HH19: =DATE(2026,12,1) -> 46357 | HI19: =DATE(2026,12,2) -> 46358 | HJ19: =DATE(2026,12,3) -> 46359 | HK19: =DATE(2026,12,4) -> 46360 | HL19: =DATE(2026,12,5) -> 46361 | HM19: =DATE(2026,12,6) -> 46362 | HN19: =DATE(2026,12,7) -> 46363 | HO19: =DATE(2026,12,8) -> 46364 | HP19: =DATE(2026,12,9) -> 46365 | HQ19: =DATE(2026,12,10) -> 46366 | HR19: =DATE(2026,12,11) -> 46367 | HS19: =DATE(2026,12,12) -> 46368 | HT19: =DATE(2026,12,13) -> 46369 | HU19: =DATE(2026,12,14) -> 46370 | HV19: =DATE(2026,12,15) -> 46371 | HW19: =DATE(2026,12,16) -> 46372 | HX19: =DATE(2026,12,17) -> 46373 | HY19: =DATE(2026,12,18) -> 46374 | HZ19: =DATE(2026,12,19) -> 46375 | IA19: =DATE(2026,12,20) -> 46376 | IB19: =DATE(2026,12,21) -> 46377 | IC19: =DATE(2026,12,22) -> 46378 | ID19: =DATE(2026,12,23) -> 46379 | IE19: =DATE(2026,12,24) -> 46380 | IF19: =DATE(2026,12,25) -> 46381 | IG19: =DATE(2026,12,26) -> 46382 | IH19: =DATE(2026,12,27) -> 46383 | II19: =DATE(2026,12,28) -> 46384 | IJ19: =DATE(2026,12,29) -> 46385 | IK19: =DATE(2026,12,30) -> 46386 | IL19: =DATE(2026,12,31) -> 46387
A20: SALDO INICIAL DO DIA | B20: =SUM(Categorias!$F$2:$F$4)+SUMIFS(Lançamentos!$F:$F,Lançamentos!$A:$A,"<"&B$19) -> 0 | C20: =B79 -> 0 | D20: =C79 -> 0 | E20: =D79 -> 0 | F20: =E79 -> 0 | G20: =F79 -> 0 | H20: =G79 -> 0 | I20: =H79 -> 0 | J20: =I79 -> 0 | ... IL20: =IK79 -> 3166.79
A21: 💰 RECEITAS
A22: Vendas de Produtos | B22: =SUMIFS(Lançamentos!$F:$F,Lançamentos!$A:$A,B$19,Lançamentos!$C:$C,"Vendas de Produtos") -> 0 | C22: =SUMIFS(Lançamentos!$F:$F,Lançamentos!$A:$A,C$19,Lançamentos!$C:$C,"Vendas de Produtos") -> 0 | D22: =SUMIFS(Lançamentos!$F:$F,Lançamentos!$A:$A,D$19,Lançamentos!$C:$C,"Vendas de Produtos") -> 0 | E22: =SUMIFS(Lançamentos!$F:$F,Lançamentos!$A:$A,E$19,Lançamentos!$C:$C,"Vendas de Produtos") -> 0 | F22: =SUMIFS(Lançamentos!$F:$F,Lançamentos!$A:$A,F$19,Lançamentos!$C:$C,"Vendas de Produtos") -> 0 | G22: =SUMIFS(Lançamentos!$F:$F,Lançamentos!$A:$A,G$19,Lançamentos!$C:$C,"Vendas de Produtos") -> 0 | H22: =SUMIFS(Lançamentos!$F:$F,Lançamentos!$A:$A,H$19,Lançamentos!$C:$C,"Vendas de Produtos") -> 0 | I22: =SUMIFS(Lançamentos!$F:$F,Lançamentos!$A:$A,I$19,Lançamentos!$C:$C,"Vendas de Produtos") -> 0 | ... IL22: =SUMIFS(Lançamentos!$F:$F,Lançamentos!$A:$A,IL$19,Lançamentos!$C:$C,"Vendas de Produtos") -> 0
A23: Vendas de Serviços | B23: =SUMIFS(Lançamentos!$F:$F,Lançamentos!$A:$A,B$19,Lançamentos!$C:$C,"Vendas de Serviços") -> 0 | C23: =SUMIFS(Lançamentos!$F:$F,Lançamentos!$A:$A,C$19,Lançamentos!$C:$C,"Vendas de Serviços") -> 0 | D23: =SUMIFS(Lançamentos!$F:$F,Lançamentos!$A:$A,D$19,Lançamentos!$C:$C,"Vendas de Serviços") -> 0 | E23: =SUMIFS(Lançamentos!$F:$F,Lançamentos!$A:$A,E$19,Lançamentos!$C:$C,"Vendas de Serviços") -> 0 | F23: =SUMIFS(Lançamentos!$F:$F,Lançamentos!$A:$A,F$19,Lançamentos!$C:$C,"Vendas de Serviços") -> 0 | G23: =SUMIFS(Lançamentos!$F:$F,Lançamentos!$A:$A,G$19,Lançamentos!$C:$C,"Vendas de Serviços") -> 0 | H23: =SUMIFS(Lançamentos!$F:$F,Lançamentos!$A:$A,H$19,Lançamentos!$C:$C,"Vendas de Serviços") -> 0 | I23: =SUMIFS(Lançamentos!$F:$F,Lançamentos!$A:$A,I$19,Lançamentos!$C:$C,"Vendas de Serviços") -> 0 | ... IL23: =SUMIFS(Lançamentos!$F:$F,Lançamentos!$A:$A,IL$19,Lançamentos!$C:$C,"Vendas de Serviços") -> 0
A24: Outras Receitas | B24: =SUMIFS(Lançamentos!$F:$F,Lançamentos!$A:$A,B$19,Lançamentos!$C:$C,"Outras Receitas") -> 0 | C24: =SUMIFS(Lançamentos!$F:$F,Lançamentos!$A:$A,C$19,Lançamentos!$C:$C,"Outras Receitas") -> 0 | D24: =SUMIFS(Lançamentos!$F:$F,Lançamentos!$A:$A,D$19,Lançamentos!$C:$C,"Outras Receitas") -> 0 | E24: =SUMIFS(Lançamentos!$F:$F,Lançamentos!$A:$A,E$19,Lançamentos!$C:$C,"Outras Receitas") -> 0 | F24: =SUMIFS(Lançamentos!$F:$F,Lançamentos!$A:$A,F$19,Lançamentos!$C:$C,"Outras Receitas") -> 0 | G24: =SUMIFS(Lançamentos!$F:$F,Lançamentos!$A:$A,G$19,Lançamentos!$C:$C,"Outras Receitas") -> 0 | H24: =SUMIFS(Lançamentos!$F:$F,Lançamentos!$A:$A,H$19,Lançamentos!$C:$C,"Outras Receitas") -> 0 | I24: =SUMIFS(Lançamentos!$F:$F,Lançamentos!$A:$A,I$19,Lançamentos!$C:$C,"Outras Receitas") -> 0 | ... IL24: =SUMIFS(Lançamentos!$F:$F,Lançamentos!$A:$A,IL$19,Lançamentos!$C:$C,"Outras Receitas") -> 0
A25: Receitas Financeiras | B25: =SUMIFS(Lançamentos!$F:$F,Lançamentos!$A:$A,B$19,Lançamentos!$C:$C,"Receitas Financeiras") -> 0 | C25: =SUMIFS(Lançamentos!$F:$F,Lançamentos!$A:$A,C$19,Lançamentos!$C:$C,"Receitas Financeiras") -> 0 | D25: =SUMIFS(Lançamentos!$F:$F,Lançamentos!$A:$A,D$19,Lançamentos!$C:$C,"Receitas Financeiras") -> 0 | E25: =SUMIFS(Lançamentos!$F:$F,Lançamentos!$A:$A,E$19,Lançamentos!$C:$C,"Receitas Financeiras") -> 0 | F25: =SUMIFS(Lançamentos!$F:$F,Lançamentos!$A:$A,F$19,Lançamentos!$C:$C,"Receitas Financeiras") -> 0 | G25: =SUMIFS(Lançamentos!$F:$F,Lançamentos!$A:$A,G$19,Lançamentos!$C:$C,"Receitas Financeiras") -> 0 | H25: =SUMIFS(Lançamentos!$F:$F,Lançamentos!$A:$A,H$19,Lançamentos!$C:$C,"Receitas Financeiras") -> 0 | I25: =SUMIFS(Lançamentos!$F:$F,Lançamentos!$A:$A,I$19,Lançamentos!$C:$C,"Receitas Financeiras") -> 0 | ... IL25: =SUMIFS(Lançamentos!$F:$F,Lançamentos!$A:$A,IL$19,Lançamentos!$C:$C,"Receitas Financeiras") -> 0
A26: Recebimento de Clientes | B26: =SUMIFS(Lançamentos!$F:$F,Lançamentos!$A:$A,B$19,Lançamentos!$C:$C,"Recebimento de Clientes") -> 0 | C26: =SUMIFS(Lançamentos!$F:$F,Lançamentos!$A:$A,C$19,Lançamentos!$C:$C,"Recebimento de Clientes") -> 0 | D26: =SUMIFS(Lançamentos!$F:$F,Lançamentos!$A:$A,D$19,Lançamentos!$C:$C,"Recebimento de Clientes") -> 0 | E26: =SUMIFS(Lançamentos!$F:$F,Lançamentos!$A:$A,E$19,Lançamentos!$C:$C,"Recebimento de Clientes") -> 0 | F26: =SUMIFS(Lançamentos!$F:$F,Lançamentos!$A:$A,F$19,Lançamentos!$C:$C,"Recebimento de Clientes") -> 0 | G26: =SUMIFS(Lançamentos!$F:$F,Lançamentos!$A:$A,G$19,Lançamentos!$C:$C,"Recebimento de Clientes") -> 0 | H26: =SUMIFS(Lançamentos!$F:$F,Lançamentos!$A:$A,H$19,Lançamentos!$C:$C,"Recebimento de Clientes") -> 0 | I26: =SUMIFS(Lançamentos!$F:$F,Lançamentos!$A:$A,I$19,Lançamentos!$C:$C,"Recebimento de Clientes") -> 0 | ... IL26: =SUMIFS(Lançamentos!$F:$F,Lançamentos!$A:$A,IL$19,Lançamentos!$C:$C,"Recebimento de Clientes") -> 0
A27: Vendas Online | B27: =SUMIFS(Lançamentos!$F:$F,Lançamentos!$A:$A,B$19,Lançamentos!$C:$C,"Vendas Online") -> 0 | C27: =SUMIFS(Lançamentos!$F:$F,Lançamentos!$A:$A,C$19,Lançamentos!$C:$C,"Vendas Online") -> 0 | D27: =SUMIFS(Lançamentos!$F:$F,Lançamentos!$A:$A,D$19,Lançamentos!$C:$C,"Vendas Online") -> 0 | E27: =SUMIFS(Lançamentos!$F:$F,Lançamentos!$A:$A,E$19,Lançamentos!$C:$C,"Vendas Online") -> 0 | F27: =SUMIFS(Lançamentos!$F:$F,Lançamentos!$A:$A,F$19,Lançamentos!$C:$C,"Vendas Online") -> 0 | G27: =SUMIFS(Lançamentos!$F:$F,Lançamentos!$A:$A,G$19,Lançamentos!$C:$C,"Vendas Online") -> 0 | H27: =SUMIFS(Lançamentos!$F:$F,Lançamentos!$A:$A,H$19,Lançamentos!$C:$C,"Vendas Online") -> 0 | I27: =SUMIFS(Lançamentos!$F:$F,Lançamentos!$A:$A,I$19,Lançamentos!$C:$C,"Vendas Online") -> 0 | ... IL27: =SUMIFS(Lançamentos!$F:$F,Lançamentos!$A:$A,IL$19,Lançamentos!$C:$C,"Vendas Online") -> 0
A28: Comissões Recebidas | B28: =SUMIFS(Lançamentos!$F:$F,Lançamentos!$A:$A,B$19,Lançamentos!$C:$C,"Comissões Recebidas") -> 0 | C28: =SUMIFS(Lançamentos!$F:$F,Lançamentos!$A:$A,C$19,Lançamentos!$C:$C,"Comissões Recebidas") -> 0 | D28: =SUMIFS(Lançamentos!$F:$F,Lançamentos!$A:$A,D$19,Lançamentos!$C:$C,"Comissões Recebidas") -> 0 | E28: =SUMIFS(Lançamentos!$F:$F,Lançamentos!$A:$A,E$19,Lançamentos!$C:$C,"Comissões Recebidas") -> 0 | F28: =SUMIFS(Lançamentos!$F:$F,Lançamentos!$A:$A,F$19,Lançamentos!$C:$C,"Comissões Recebidas") -> 0 | G28: =SUMIFS(Lançamentos!$F:$F,Lançamentos!$A:$A,G$19,Lançamentos!$C:$C,"Comissões Recebidas") -> 0 | H28: =SUMIFS(Lançamentos!$F:$F,Lançamentos!$A:$A,H$19,Lançamentos!$C:$C,"Comissões Recebidas") -> 0 | I28: =SUMIFS(Lançamentos!$F:$F,Lançamentos!$A:$A,I$19,Lançamentos!$C:$C,"Comissões Recebidas") -> 0 | ... IL28: =SUMIFS(Lançamentos!$F:$F,Lançamentos!$A:$A,IL$19,Lançamentos!$C:$C,"Comissões Recebidas") -> 0
A29: Aluguel Recebido | B29: =SUMIFS(Lançamentos!$F:$F,Lançamentos!$A:$A,B$19,Lançamentos!$C:$C,"Aluguel Recebido") -> 0 | C29: =SUMIFS(Lançamentos!$F:$F,Lançamentos!$A:$A,C$19,Lançamentos!$C:$C,"Aluguel Recebido") -> 0 | D29: =SUMIFS(Lançamentos!$F:$F,Lançamentos!$A:$A,D$19,Lançamentos!$C:$C,"Aluguel Recebido") -> 0 | E29: =SUMIFS(Lançamentos!$F:$F,Lançamentos!$A:$A,E$19,Lançamentos!$C:$C,"Aluguel Recebido") -> 0 | F29: =SUMIFS(Lançamentos!$F:$F,Lançamentos!$A:$A,F$19,Lançamentos!$C:$C,"Aluguel Recebido") -> 0 | G29: =SUMIFS(Lançamentos!$F:$F,Lançamentos!$A:$A,G$19,Lançamentos!$C:$C,"Aluguel Recebido") -> 0 | H29: =SUMIFS(Lançamentos!$F:$F,Lançamentos!$A:$A,H$19,Lançamentos!$C:$C,"Aluguel Recebido") -> 0 | I29: =SUMIFS(Lançamentos!$F:$F,Lançamentos!$A:$A,I$19,Lançamentos!$C:$C,"Aluguel Recebido") -> 0 | ... IL29: =SUMIFS(Lançamentos!$F:$F,Lançamentos!$A:$A,IL$19,Lançamentos!$C:$C,"Aluguel Recebido") -> 0
A30: Reembolsos | B30: =SUMIFS(Lançamentos!$F:$F,Lançamentos!$A:$A,B$19,Lançamentos!$C:$C,"Reembolsos") -> 0 | C30: =SUMIFS(Lançamentos!$F:$F,Lançamentos!$A:$A,C$19,Lançamentos!$C:$C,"Reembolsos") -> 0 | D30: =SUMIFS(Lançamentos!$F:$F,Lançamentos!$A:$A,D$19,Lançamentos!$C:$C,"Reembolsos") -> 0 | E30: =SUMIFS(Lançamentos!$F:$F,Lançamentos!$A:$A,E$19,Lançamentos!$C:$C,"Reembolsos") -> 0 | F30: =SUMIFS(Lançamentos!$F:$F,Lançamentos!$A:$A,F$19,Lançamentos!$C:$C,"Reembolsos") -> 0 | G30: =SUMIFS(Lançamentos!$F:$F,Lançamentos!$A:$A,G$19,Lançamentos!$C:$C,"Reembolsos") -> 0 | H30: =SUMIFS(Lançamentos!$F:$F,Lançamentos!$A:$A,H$19,Lançamentos!$C:$C,"Reembolsos") -> 0 | I30: =SUMIFS(Lançamentos!$F:$F,Lançamentos!$A:$A,I$19,Lançamentos!$C:$C,"Reembolsos") -> 0 | ... IL30: =SUMIFS(Lançamentos!$F:$F,Lançamentos!$A:$A,IL$19,Lançamentos!$C:$C,"Reembolsos") -> 0
A31: Aporte de Sócios | B31: =SUMIFS(Lançamentos!$F:$F,Lançamentos!$A:$A,B$19,Lançamentos!$C:$C,"Aporte de Sócios") -> 0 | C31: =SUMIFS(Lançamentos!$F:$F,Lançamentos!$A:$A,C$19,Lançamentos!$C:$C,"Aporte de Sócios") -> 0 | D31: =SUMIFS(Lançamentos!$F:$F,Lançamentos!$A:$A,D$19,Lançamentos!$C:$C,"Aporte de Sócios") -> 0 | E31: =SUMIFS(Lançamentos!$F:$F,Lançamentos!$A:$A,E$19,Lançamentos!$C:$C,"Aporte de Sócios") -> 0 | F31: =SUMIFS(Lançamentos!$F:$F,Lançamentos!$A:$A,F$19,Lançamentos!$C:$C,"Aporte de Sócios") -> 0 | G31: =SUMIFS(Lançamentos!$F:$F,Lançamentos!$A:$A,G$19,Lançamentos!$C:$C,"Aporte de Sócios") -> 0 | H31: =SUMIFS(Lançamentos!$F:$F,Lançamentos!$A:$A,H$19,Lançamentos!$C:$C,"Aporte de Sócios") -> 0 | I31: =SUMIFS(Lançamentos!$F:$F,Lançamentos!$A:$A,I$19,Lançamentos!$C:$C,"Aporte de Sócios") -> 0 | ... IL31: =SUMIFS(Lançamentos!$F:$F,Lançamentos!$A:$A,IL$19,Lançamentos!$C:$C,"Aporte de Sócios") -> 0
A32: Empréstimo Recebido | B32: =SUMIFS(Lançamentos!$F:$F,Lançamentos!$A:$A,B$19,Lançamentos!$C:$C,"Empréstimo Recebido") -> 0 | C32: =SUMIFS(Lançamentos!$F:$F,Lançamentos!$A:$A,C$19,Lançamentos!$C:$C,"Empréstimo Recebido") -> 0 | D32: =SUMIFS(Lançamentos!$F:$F,Lançamentos!$A:$A,D$19,Lançamentos!$C:$C,"Empréstimo Recebido") -> 0 | E32: =SUMIFS(Lançamentos!$F:$F,Lançamentos!$A:$A,E$19,Lançamentos!$C:$C,"Empréstimo Recebido") -> 0 | F32: =SUMIFS(Lançamentos!$F:$F,Lançamentos!$A:$A,F$19,Lançamentos!$C:$C,"Empréstimo Recebido") -> 0 | G32: =SUMIFS(Lançamentos!$F:$F,Lançamentos!$A:$A,G$19,Lançamentos!$C:$C,"Empréstimo Recebido") -> 0 | H32: =SUMIFS(Lançamentos!$F:$F,Lançamentos!$A:$A,H$19,Lançamentos!$C:$C,"Empréstimo Recebido") -> 0 | I32: =SUMIFS(Lançamentos!$F:$F,Lançamentos!$A:$A,I$19,Lançamentos!$C:$C,"Empréstimo Recebido") -> 0 | ... IL32: =SUMIFS(Lançamentos!$F:$F,Lançamentos!$A:$A,IL$19,Lançamentos!$C:$C,"Empréstimo Recebido") -> 0
A33: TOTAL ENTRADAS | B33: =SUM(B22:B32) -> 0 | C33: =SUM(C22:C32) -> 0 | D33: =SUM(D22:D32) -> 0 | E33: =SUM(E22:E32) -> 0 | F33: =SUM(F22:F32) -> 0 | G33: =SUM(G22:G32) -> 0 | H33: =SUM(H22:H32) -> 0 | I33: =SUM(I22:I32) -> 0 | ... IL33: =SUM(IL22:IL32) -> 0
A34: 💸 DESPESAS
A35: Impostos sobre Vendas | B35: =SUMIFS(Lançamentos!$F:$F,Lançamentos!$A:$A,B$19,Lançamentos!$C:$C,"Impostos sobre Vendas") -> 0 | C35: =SUMIFS(Lançamentos!$F:$F,Lançamentos!$A:$A,C$19,Lançamentos!$C:$C,"Impostos sobre Vendas") -> 0 | D35: =SUMIFS(Lançamentos!$F:$F,Lançamentos!$A:$A,D$19,Lançamentos!$C:$C,"Impostos sobre Vendas") -> 0 | E35: =SUMIFS(Lançamentos!$F:$F,Lançamentos!$A:$A,E$19,Lançamentos!$C:$C,"Impostos sobre Vendas") -> 0 | F35: =SUMIFS(Lançamentos!$F:$F,Lançamentos!$A:$A,F$19,Lançamentos!$C:$C,"Impostos sobre Vendas") -> 0 | G35: =SUMIFS(Lançamentos!$F:$F,Lançamentos!$A:$A,G$19,Lançamentos!$C:$C,"Impostos sobre Vendas") -> 0 | H35: =SUMIFS(Lançamentos!$F:$F,Lançamentos!$A:$A,H$19,Lançamentos!$C:$C,"Impostos sobre Vendas") -> 0 | I35: =SUMIFS(Lançamentos!$F:$F,Lançamentos!$A:$A,I$19,Lançamentos!$C:$C,"Impostos sobre Vendas") -> 0 | ... IL35: =SUMIFS(Lançamentos!$F:$F,Lançamentos!$A:$A,IL$19,Lançamentos!$C:$C,"Impostos sobre Vendas") -> 0
A36: Devoluções | B36: =SUMIFS(Lançamentos!$F:$F,Lançamentos!$A:$A,B$19,Lançamentos!$C:$C,"Devoluções") -> 0 | C36: =SUMIFS(Lançamentos!$F:$F,Lançamentos!$A:$A,C$19,Lançamentos!$C:$C,"Devoluções") -> 0 | D36: =SUMIFS(Lançamentos!$F:$F,Lançamentos!$A:$A,D$19,Lançamentos!$C:$C,"Devoluções") -> 0 | E36: =SUMIFS(Lançamentos!$F:$F,Lançamentos!$A:$A,E$19,Lançamentos!$C:$C,"Devoluções") -> 0 | F36: =SUMIFS(Lançamentos!$F:$F,Lançamentos!$A:$A,F$19,Lançamentos!$C:$C,"Devoluções") -> 0 | G36: =SUMIFS(Lançamentos!$F:$F,Lançamentos!$A:$A,G$19,Lançamentos!$C:$C,"Devoluções") -> 0 | H36: =SUMIFS(Lançamentos!$F:$F,Lançamentos!$A:$A,H$19,Lançamentos!$C:$C,"Devoluções") -> 0 | I36: =SUMIFS(Lançamentos!$F:$F,Lançamentos!$A:$A,I$19,Lançamentos!$C:$C,"Devoluções") -> 0 | ... IL36: =SUMIFS(Lançamentos!$F:$F,Lançamentos!$A:$A,IL$19,Lançamentos!$C:$C,"Devoluções") -> 0
A37: Custo de Mercadoria Vendida | B37: =SUMIFS(Lançamentos!$F:$F,Lançamentos!$A:$A,B$19,Lançamentos!$C:$C,"Custo de Mercadoria Vendida") -> 0 | C37: =SUMIFS(Lançamentos!$F:$F,Lançamentos!$A:$A,C$19,Lançamentos!$C:$C,"Custo de Mercadoria Vendida") -> 0 | D37: =SUMIFS(Lançamentos!$F:$F,Lançamentos!$A:$A,D$19,Lançamentos!$C:$C,"Custo de Mercadoria Vendida") -> 0 | E37: =SUMIFS(Lançamentos!$F:$F,Lançamentos!$A:$A,E$19,Lançamentos!$C:$C,"Custo de Mercadoria Vendida") -> 0 | F37: =SUMIFS(Lançamentos!$F:$F,Lançamentos!$A:$A,F$19,Lançamentos!$C:$C,"Custo de Mercadoria Vendida") -> 0 | G37: =SUMIFS(Lançamentos!$F:$F,Lançamentos!$A:$A,G$19,Lançamentos!$C:$C,"Custo de Mercadoria Vendida") -> 0 | H37: =SUMIFS(Lançamentos!$F:$F,Lançamentos!$A:$A,H$19,Lançamentos!$C:$C,"Custo de Mercadoria Vendida") -> 0 | I37: =SUMIFS(Lançamentos!$F:$F,Lançamentos!$A:$A,I$19,Lançamentos!$C:$C,"Custo de Mercadoria Vendida") -> 0 | ... IL37: =SUMIFS(Lançamentos!$F:$F,Lançamentos!$A:$A,IL$19,Lançamentos!$C:$C,"Custo de Mercadoria Vendida") -> 0
A38: Custo de Serviços Prestados | B38: =SUMIFS(Lançamentos!$F:$F,Lançamentos!$A:$A,B$19,Lançamentos!$C:$C,"Custo de Serviços Prestados") -> 0 | C38: =SUMIFS(Lançamentos!$F:$F,Lançamentos!$A:$A,C$19,Lançamentos!$C:$C,"Custo de Serviços Prestados") -> 0 | D38: =SUMIFS(Lançamentos!$F:$F,Lançamentos!$A:$A,D$19,Lançamentos!$C:$C,"Custo de Serviços Prestados") -> 0 | E38: =SUMIFS(Lançamentos!$F:$F,Lançamentos!$A:$A,E$19,Lançamentos!$C:$C,"Custo de Serviços Prestados") -> 0 | F38: =SUMIFS(Lançamentos!$F:$F,Lançamentos!$A:$A,F$19,Lançamentos!$C:$C,"Custo de Serviços Prestados") -> 0 | G38: =SUMIFS(Lançamentos!$F:$F,Lançamentos!$A:$A,G$19,Lançamentos!$C:$C,"Custo de Serviços Prestados") -> 0 | H38: =SUMIFS(Lançamentos!$F:$F,Lançamentos!$A:$A,H$19,Lançamentos!$C:$C,"Custo de Serviços Prestados") -> 0 | I38: =SUMIFS(Lançamentos!$F:$F,Lançamentos!$A:$A,I$19,Lançamentos!$C:$C,"Custo de Serviços Prestados") -> 0 | ... IL38: =SUMIFS(Lançamentos!$F:$F,Lançamentos!$A:$A,IL$19,Lançamentos!$C:$C,"Custo de Serviços Prestados") -> 0
A39: Salários e Encargos | B39: =SUMIFS(Lançamentos!$F:$F,Lançamentos!$A:$A,B$19,Lançamentos!$C:$C,"Salários e Encargos") -> 0 | C39: =SUMIFS(Lançamentos!$F:$F,Lançamentos!$A:$A,C$19,Lançamentos!$C:$C,"Salários e Encargos") -> 0 | D39: =SUMIFS(Lançamentos!$F:$F,Lançamentos!$A:$A,D$19,Lançamentos!$C:$C,"Salários e Encargos") -> 0 | E39: =SUMIFS(Lançamentos!$F:$F,Lançamentos!$A:$A,E$19,Lançamentos!$C:$C,"Salários e Encargos") -> 0 | F39: =SUMIFS(Lançamentos!$F:$F,Lançamentos!$A:$A,F$19,Lançamentos!$C:$C,"Salários e Encargos") -> 0 | G39: =SUMIFS(Lançamentos!$F:$F,Lançamentos!$A:$A,G$19,Lançamentos!$C:$C,"Salários e Encargos") -> 0 | H39: =SUMIFS(Lançamentos!$F:$F,Lançamentos!$A:$A,H$19,Lançamentos!$C:$C,"Salários e Encargos") -> 0 | I39: =SUMIFS(Lançamentos!$F:$F,Lançamentos!$A:$A,I$19,Lançamentos!$C:$C,"Salários e Encargos") -> 0 | ... IL39: =SUMIFS(Lançamentos!$F:$F,Lançamentos!$A:$A,IL$19,Lançamentos!$C:$C,"Salários e Encargos") -> 0
A40: Aluguel | B40: =SUMIFS(Lançamentos!$F:$F,Lançamentos!$A:$A,B$19,Lançamentos!$C:$C,"Aluguel") -> 0 | C40: =SUMIFS(Lançamentos!$F:$F,Lançamentos!$A:$A,C$19,Lançamentos!$C:$C,"Aluguel") -> 0 | D40: =SUMIFS(Lançamentos!$F:$F,Lançamentos!$A:$A,D$19,Lançamentos!$C:$C,"Aluguel") -> 0 | E40: =SUMIFS(Lançamentos!$F:$F,Lançamentos!$A:$A,E$19,Lançamentos!$C:$C,"Aluguel") -> 0 | F40: =SUMIFS(Lançamentos!$F:$F,Lançamentos!$A:$A,F$19,Lançamentos!$C:$C,"Aluguel") -> 0 | G40: =SUMIFS(Lançamentos!$F:$F,Lançamentos!$A:$A,G$19,Lançamentos!$C:$C,"Aluguel") -> 0 | H40: =SUMIFS(Lançamentos!$F:$F,Lançamentos!$A:$A,H$19,Lançamentos!$C:$C,"Aluguel") -> 0 | I40: =SUMIFS(Lançamentos!$F:$F,Lançamentos!$A:$A,I$19,Lançamentos!$C:$C,"Aluguel") -> 0 | ... IL40: =SUMIFS(Lançamentos!$F:$F,Lançamentos!$A:$A,IL$19,Lançamentos!$C:$C,"Aluguel") -> 0
A41: Água, Luz e Internet | B41: =SUMIFS(Lançamentos!$F:$F,Lançamentos!$A:$A,B$19,Lançamentos!$C:$C,"Água, Luz e Internet") -> 0 | C41: =SUMIFS(Lançamentos!$F:$F,Lançamentos!$A:$A,C$19,Lançamentos!$C:$C,"Água, Luz e Internet") -> 0 | D41: =SUMIFS(Lançamentos!$F:$F,Lançamentos!$A:$A,D$19,Lançamentos!$C:$C,"Água, Luz e Internet") -> 0 | E41: =SUMIFS(Lançamentos!$F:$F,Lançamentos!$A:$A,E$19,Lançamentos!$C:$C,"Água, Luz e Internet") -> 0 | F41: =SUMIFS(Lançamentos!$F:$F,Lançamentos!$A:$A,F$19,Lançamentos!$C:$C,"Água, Luz e Internet") -> 0 | G41: =SUMIFS(Lançamentos!$F:$F,Lançamentos!$A:$A,G$19,Lançamentos!$C:$C,"Água, Luz e Internet") -> 0 | H41: =SUMIFS(Lançamentos!$F:$F,Lançamentos!$A:$A,H$19,Lançamentos!$C:$C,"Água, Luz e Internet") -> 0 | I41: =SUMIFS(Lançamentos!$F:$F,Lançamentos!$A:$A,I$19,Lançamentos!$C:$C,"Água, Luz e Internet") -> 0 | ... IL41: =SUMIFS(Lançamentos!$F:$F,Lançamentos!$A:$A,IL$19,Lançamentos!$C:$C,"Água, Luz e Internet") -> 0
A42: Material de Escritório | B42: =SUMIFS(Lançamentos!$F:$F,Lançamentos!$A:$A,B$19,Lançamentos!$C:$C,"Material de Escritório") -> 0 | C42: =SUMIFS(Lançamentos!$F:$F,Lançamentos!$A:$A,C$19,Lançamentos!$C:$C,"Material de Escritório") -> 0 | D42: =SUMIFS(Lançamentos!$F:$F,Lançamentos!$A:$A,D$19,Lançamentos!$C:$C,"Material de Escritório") -> 0 | E42: =SUMIFS(Lançamentos!$F:$F,Lançamentos!$A:$A,E$19,Lançamentos!$C:$C,"Material de Escritório") -> 0 | F42: =SUMIFS(Lançamentos!$F:$F,Lançamentos!$A:$A,F$19,Lançamentos!$C:$C,"Material de Escritório") -> 0 | G42: =SUMIFS(Lançamentos!$F:$F,Lançamentos!$A:$A,G$19,Lançamentos!$C:$C,"Material de Escritório") -> 0 | H42: =SUMIFS(Lançamentos!$F:$F,Lançamentos!$A:$A,H$19,Lançamentos!$C:$C,"Material de Escritório") -> 0 | I42: =SUMIFS(Lançamentos!$F:$F,Lançamentos!$A:$A,I$19,Lançamentos!$C:$C,"Material de Escritório") -> 0 | ... IL42: =SUMIFS(Lançamentos!$F:$F,Lançamentos!$A:$A,IL$19,Lançamentos!$C:$C,"Material de Escritório") -> 0
A43: Marketing e Publicidade | B43: =SUMIFS(Lançamentos!$F:$F,Lançamentos!$A:$A,B$19,Lançamentos!$C:$C,"Marketing e Publicidade") -> 0 | C43: =SUMIFS(Lançamentos!$F:$F,Lançamentos!$A:$A,C$19,Lançamentos!$C:$C,"Marketing e Publicidade") -> 0 | D43: =SUMIFS(Lançamentos!$F:$F,Lançamentos!$A:$A,D$19,Lançamentos!$C:$C,"Marketing e Publicidade") -> 0 | E43: =SUMIFS(Lançamentos!$F:$F,Lançamentos!$A:$A,E$19,Lançamentos!$C:$C,"Marketing e Publicidade") -> 0 | F43: =SUMIFS(Lançamentos!$F:$F,Lançamentos!$A:$A,F$19,Lançamentos!$C:$C,"Marketing e Publicidade") -> 0 | G43: =SUMIFS(Lançamentos!$F:$F,Lançamentos!$A:$A,G$19,Lançamentos!$C:$C,"Marketing e Publicidade") -> 0 | H43: =SUMIFS(Lançamentos!$F:$F,Lançamentos!$A:$A,H$19,Lançamentos!$C:$C,"Marketing e Publicidade") -> 0 | I43: =SUMIFS(Lançamentos!$F:$F,Lançamentos!$A:$A,I$19,Lançamentos!$C:$C,"Marketing e Publicidade") -> 0 | ... IL43: =SUMIFS(Lançamentos!$F:$F,Lançamentos!$A:$A,IL$19,Lançamentos!$C:$C,"Marketing e Publicidade") -> 0
A44: Manutenção | B44: =SUMIFS(Lançamentos!$F:$F,Lançamentos!$A:$A,B$19,Lançamentos!$C:$C,"Manutenção") -> 0 | C44: =SUMIFS(Lançamentos!$F:$F,Lançamentos!$A:$A,C$19,Lançamentos!$C:$C,"Manutenção") -> 0 | D44: =SUMIFS(Lançamentos!$F:$F,Lançamentos!$A:$A,D$19,Lançamentos!$C:$C,"Manutenção") -> 0 | E44: =SUMIFS(Lançamentos!$F:$F,Lançamentos!$A:$A,E$19,Lançamentos!$C:$C,"Manutenção") -> 0 | F44: =SUMIFS(Lançamentos!$F:$F,Lançamentos!$A:$A,F$19,Lançamentos!$C:$C,"Manutenção") -> 0 | G44: =SUMIFS(Lançamentos!$F:$F,Lançamentos!$A:$A,G$19,Lançamentos!$C:$C,"Manutenção") -> 0 | H44: =SUMIFS(Lançamentos!$F:$F,Lançamentos!$A:$A,H$19,Lançamentos!$C:$C,"Manutenção") -> 0 | I44: =SUMIFS(Lançamentos!$F:$F,Lançamentos!$A:$A,I$19,Lançamentos!$C:$C,"Manutenção") -> 0 | ... IL44: =SUMIFS(Lançamentos!$F:$F,Lançamentos!$A:$A,IL$19,Lançamentos!$C:$C,"Manutenção") -> 0
A45: Transporte e Viagens | B45: =SUMIFS(Lançamentos!$F:$F,Lançamentos!$A:$A,B$19,Lançamentos!$C:$C,"Transporte e Viagens") -> 0 | C45: =SUMIFS(Lançamentos!$F:$F,Lançamentos!$A:$A,C$19,Lançamentos!$C:$C,"Transporte e Viagens") -> 0 | D45: =SUMIFS(Lançamentos!$F:$F,Lançamentos!$A:$A,D$19,Lançamentos!$C:$C,"Transporte e Viagens") -> 0 | E45: =SUMIFS(Lançamentos!$F:$F,Lançamentos!$A:$A,E$19,Lançamentos!$C:$C,"Transporte e Viagens") -> 0 | F45: =SUMIFS(Lançamentos!$F:$F,Lançamentos!$A:$A,F$19,Lançamentos!$C:$C,"Transporte e Viagens") -> 0 | G45: =SUMIFS(Lançamentos!$F:$F,Lançamentos!$A:$A,G$19,Lançamentos!$C:$C,"Transporte e Viagens") -> 0 | H45: =SUMIFS(Lançamentos!$F:$F,Lançamentos!$A:$A,H$19,Lançamentos!$C:$C,"Transporte e Viagens") -> 0 | I45: =SUMIFS(Lançamentos!$F:$F,Lançamentos!$A:$A,I$19,Lançamentos!$C:$C,"Transporte e Viagens") -> 0 | ... IL45: =SUMIFS(Lançamentos!$F:$F,Lançamentos!$A:$A,IL$19,Lançamentos!$C:$C,"Transporte e Viagens") -> 0
...

Sheet Dashboard
B2: DASHBOARD FINANCEIRO
B4: FILTROS
B5: Mês Inicial | C5: Mês Final | D5: Categoria | E5: Banco
B6: =DATE(YEAR(TODAY()),1,1) -> 46023 | C6: =DATE(YEAR(TODAY()),12,1) -> 46357 | D6: Todas | E6: Todos
B8: ENTRADAS | C8: SAÍDAS | D8: RESULTADO | E8: SALDO ATUAL
B9: =SUMIFS(Lançamentos!$F:$F,Lançamentos!$H:$H,">="&$B$6,Lançamentos!$H:$H,"<="&$C$6,Lançamentos!$C:$C,IF($D$6="Todas","*",$D$6),Lançamentos!$G:$G,IF($E$6="Todos","*",$E$6),Lançamentos!$D:$D,"Entrada") -> 20878.13 | C9: =SUMIFS(Lançamentos!$F:$F,Lançamentos!$H:$H,">="&$B$6,Lançamentos!$H:$H,"<="&$C$6,Lançamentos!$C:$C,IF($D$6="Todas","*",$D$6),Lançamentos!$G:$G,IF($E$6="Todos","*",$E$6),Lançamentos!$D:$D,"Saída") -> -17711.34 | D9: =B9+C9 -> 3166.79 | E9: =SUM(Categorias!F2:F4)+SUMIFS(Lançamentos!$F:$F,Lançamentos!$H:$H,"<="&$C$6) -> 3166.79
B11: EVOLUÇÃO MENSAL | H11: TOP DESPESAS POR CATEGORIA
B12: Mês | C12: Entradas | D12: Saídas | E12: Resultado | F12: Saldo Acum. | H12: Categoria | I12: Valor | J12: % | L12: Categoria (aux) | M12: Tipo (aux) | N12: Valor (aux)
B13: =IF(EDATE($B$6,0)<=$C$6,EDATE($B$6,0),"") -> 46023 | C13: =IF(B13="","",SUMIFS(Lançamentos!$F:$F,Lançamentos!$H:$H,B13,Lançamentos!$C:$C,IF($D$6="Todas","*",$D$6),Lançamentos!$G:$G,IF($E$6="Todos","*",$E$6),Lançamentos!$D:$D,"Entrada")) -> 0 | D13: =IF(B13="","",SUMIFS(Lançamentos!$F:$F,Lançamentos!$H:$H,B13,Lançamentos!$C:$C,IF($D$6="Todas","*",$D$6),Lançamentos!$G:$G,IF($E$6="Todos","*",$E$6),Lançamentos!$D:$D,"Saída")) -> 0 | E13: =IF(B13="","",C13+D13) -> 0 | F13: =IF(B13="","",SUM(Categorias!F2:F4)+E13) -> 0 | H13: =IFERROR(INDEX($L$13:$L$65,MATCH(I13,$N$13:$N$65,0)),"") -> Pagamento de Fornecedores | I13: {=IFERROR(SMALL(IF(($M$13:$M$65="Saída")*($N$13:$N$65<0),$N$13:$N$65),1),"")} -> -14865.69 | J13: =IFERROR(I13/SUMIFS($N$13:$N$65,$M$13:$M$65,"Saída"),0) -> 0.83933175 | L13: =Categorias!A2 -> Vendas de Produtos | M13: =Categorias!B2 -> Entrada | N13: =SUMIFS(Lançamentos!$F:$F,Lançamentos!$H:$H,">="&$B$6,Lançamentos!$H:$H,"<="&$C$6,Lançamentos!$C:$C,L13,Lançamentos!$G:$G,IF($E$6="Todos","*",$E$6)) -> 20878.13
B14: =IF(EDATE($B$6,1)<=$C$6,EDATE($B$6,1),"") -> 46054 | C14: =IF(B14="","",SUMIFS(Lançamentos!$F:$F,Lançamentos!$H:$H,B14,Lançamentos!$C:$C,IF($D$6="Todas","*",$D$6),Lançamentos!$G:$G,IF($E$6="Todos","*",$E$6),Lançamentos!$D:$D,"Entrada")) -> 0 | D14: =IF(B14="","",SUMIFS(Lançamentos!$F:$F,Lançamentos!$H:$H,B14,Lançamentos!$C:$C,IF($D$6="Todas","*",$D$6),Lançamentos!$G:$G,IF($E$6="Todos","*",$E$6),Lançamentos!$D:$D,"Saída")) -> 0 | E14: =IF(B14="","",C14+D14) -> 0 | F14: =IF(B14="","",F13+E14) -> 0 | H14: =IFERROR(INDEX($L$13:$L$65,MATCH(I14,$N$13:$N$65,0)),"") -> Aluguel | I14: {=IFERROR(SMALL(IF(($M$13:$M$65="Saída")*($N$13:$N$65<0),$N$13:$N$65),2),"")} -> -2474.18 | J14: =IFERROR(I14/SUMIFS($N$13:$N$65,$M$13:$M$65,"Saída"),0) -> 0.13969468 | L14: =Categorias!A3 -> Vendas de Serviços | M14: =Categorias!B3 -> Entrada | N14: =SUMIFS(Lançamentos!$F:$F,Lançamentos!$H:$H,">="&$B$6,Lançamentos!$H:$H,"<="&$C$6,Lançamentos!$C:$C,L14,Lançamentos!$G:$G,IF($E$6="Todos","*",$E$6)) -> 0
B15: =IF(EDATE($B$6,2)<=$C$6,EDATE($B$6,2),"") -> 46082 | C15: =IF(B15="","",SUMIFS(Lançamentos!$F:$F,Lançamentos!$H:$H,B15,Lançamentos!$C:$C,IF($D$6="Todas","*",$D$6),Lançamentos!$G:$G,IF($E$6="Todos","*",$E$6),Lançamentos!$D:$D,"Entrada")) -> 0 | D15: =IF(B15="","",SUMIFS(Lançamentos!$F:$F,Lançamentos!$H:$H,B15,Lançamentos!$C:$C,IF($D$6="Todas","*",$D$6),Lançamentos!$G:$G,IF($E$6="Todos","*",$E$6),Lançamentos!$D:$D,"Saída")) -> 0 | E15: =IF(B15="","",C15+D15) -> 0 | F15: =IF(B15="","",F14+E15) -> 0 | H15: =IFERROR(INDEX($L$13:$L$65,MATCH(I15,$N$13:$N$65,0)),"") -> Seguros | I15: {=IFERROR(SMALL(IF(($M$13:$M$65="Saída")*($N$13:$N$65<0),$N$13:$N$65),3),"")} -> -356.9 | J15: =IFERROR(I15/SUMIFS($N$13:$N$65,$M$13:$M$65,"Saída"),0) -> 0.020150932 | L15: =Categorias!A4 -> Outras Receitas | M15: =Categorias!B4 -> Entrada | N15: =SUMIFS(Lançamentos!$F:$F,Lançamentos!$H:$H,">="&$B$6,Lançamentos!$H:$H,"<="&$C$6,Lançamentos!$C:$C,L15,Lançamentos!$G:$G,IF($E$6="Todos","*",$E$6)) -> 0
B16: =IF(EDATE($B$6,3)<=$C$6,EDATE($B$6,3),"") -> 46113 | C16: =IF(B16="","",SUMIFS(Lançamentos!$F:$F,Lançamentos!$H:$H,B16,Lançamentos!$C:$C,IF($D$6="Todas","*",$D$6),Lançamentos!$G:$G,IF($E$6="Todos","*",$E$6),Lançamentos!$D:$D,"Entrada")) -> 0 | D16: =IF(B16="","",SUMIFS(Lançamentos!$F:$F,Lançamentos!$H:$H,B16,Lançamentos!$C:$C,IF($D$6="Todas","*",$D$6),Lançamentos!$G:$G,IF($E$6="Todos","*",$E$6),Lançamentos!$D:$D,"Saída")) -> 0 | E16: =IF(B16="","",C16+D16) -> 0 | F16: =IF(B16="","",F15+E16) -> 0 | H16: =IFERROR(INDEX($L$13:$L$65,MATCH(I16,$N$13:$N$65,0)),"") -> Juros e Tarifas Bancárias | I16: {=IFERROR(SMALL(IF(($M$13:$M$65="Saída")*($N$13:$N$65<0),$N$13:$N$65),4),"")} -> -14.57 | J16: =IFERROR(I16/SUMIFS($N$13:$N$65,$M$13:$M$65,"Saída"),0) -> 0.0008226368 | L16: =Categorias!A5 -> Impostos sobre Vendas | M16: =Categorias!B5 -> Saída | N16: =SUMIFS(Lançamentos!$F:$F,Lançamentos!$H:$H,">="&$B$6,Lançamentos!$H:$H,"<="&$C$6,Lançamentos!$C:$C,L16,Lançamentos!$G:$G,IF($E$6="Todos","*",$E$6)) -> 0
B17: =IF(EDATE($B$6,4)<=$C$6,EDATE($B$6,4),"") -> 46143 | C17: =IF(B17="","",SUMIFS(Lançamentos!$F:$F,Lançamentos!$H:$H,B17,Lançamentos!$C:$C,IF($D$6="Todas","*",$D$6),Lançamentos!$G:$G,IF($E$6="Todos","*",$E$6),Lançamentos!$D:$D,"Entrada")) -> 0 | D17: =IF(B17="","",SUMIFS(Lançamentos!$F:$F,Lançamentos!$H:$H,B17,Lançamentos!$C:$C,IF($D$6="Todas","*",$D$6),Lançamentos!$G:$G,IF($E$6="Todos","*",$E$6),Lançamentos!$D:$D,"Saída")) -> 0 | E17: =IF(B17="","",C17+D17) -> 0 | F17: =IF(B17="","",F16+E17) -> 0 | H17: =IFERROR(INDEX($L$13:$L$65,MATCH(I17,$N$13:$N$65,0)),"") | I17: {=IFERROR(SMALL(IF(($M$13:$M$65="Saída")*($N$13:$N$65<0),$N$13:$N$65),5),"")} | J17: =IFERROR(I17/SUMIFS($N$13:$N$65,$M$13:$M$65,"Saída"),0) -> 0 | L17: =Categorias!A6 -> Devoluções | M17: =Categorias!B6 -> Saída | N17: =SUMIFS(Lançamentos!$F:$F,Lançamentos!$H:$H,">="&$B$6,Lançamentos!$H:$H,"<="&$C$6,Lançamentos!$C:$C,L17,Lançamentos!$G:$G,IF($E$6="Todos","*",$E$6)) -> 0
B18: =IF(EDATE($B$6,5)<=$C$6,EDATE($B$6,5),"") -> 46174 | C18: =IF(B18="","",SUMIFS(Lançamentos!$F:$F,Lançamentos!$H:$H,B18,Lançamentos!$C:$C,IF($D$6="Todas","*",$D$6),Lançamentos!$G:$G,IF($E$6="Todos","*",$E$6),Lançamentos!$D:$D,"Entrada")) -> 20878.13 | D18: =IF(B18="","",SUMIFS(Lançamentos!$F:$F,Lançamentos!$H:$H,B18,Lançamentos!$C:$C,IF($D$6="Todas","*",$D$6),Lançamentos!$G:$G,IF($E$6="Todos","*",$E$6),Lançamentos!$D:$D,"Saída")) -> -17711.34 | E18: =IF(B18="","",C18+D18) -> 3166.79 | F18: =IF(B18="","",F17+E18) -> 3166.79 | H18: =IFERROR(INDEX($L$13:$L$65,MATCH(I18,$N$13:$N$65,0)),"") | I18: {=IFERROR(SMALL(IF(($M$13:$M$65="Saída")*($N$13:$N$65<0),$N$13:$N$65),6),"")} | J18: =IFERROR(I18/SUMIFS($N$13:$N$65,$M$13:$M$65,"Saída"),0) -> 0 | L18: =Categorias!A7 -> Custo de Mercadoria Vendida | M18: =Categorias!B7 -> Saída | N18: =SUMIFS(Lançamentos!$F:$F,Lançamentos!$H:$H,">="&$B$6,Lançamentos!$H:$H,"<="&$C$6,Lançamentos!$C:$C,L18,Lançamentos!$G:$G,IF($E$6="Todos","*",$E$6)) -> 0
B19: =IF(EDATE($B$6,6)<=$C$6,EDATE($B$6,6),"") -> 46204 | C19: =IF(B19="","",SUMIFS(Lançamentos!$F:$F,Lançamentos!$H:$H,B19,Lançamentos!$C:$C,IF($D$6="Todas","*",$D$6),Lançamentos!$G:$G,IF($E$6="Todos","*",$E$6),Lançamentos!$D:$D,"Entrada")) -> 0 | D19: =IF(B19="","",SUMIFS(Lançamentos!$F:$F,Lançamentos!$H:$H,B19,Lançamentos!$C:$C,IF($D$6="Todas","*",$D$6),Lançamentos!$G:$G,IF($E$6="Todos","*",$E$6),Lançamentos!$D:$D,"Saída")) -> 0 | E19: =IF(B19="","",C19+D19) -> 0 | F19: =IF(B19="","",F18+E19) -> 3166.79 | H19: =IFERROR(INDEX($L$13:$L$65,MATCH(I19,$N$13:$N$65,0)),"") | I19: {=IFERROR(SMALL(IF(($M$13:$M$65="Saída")*($N$13:$N$65<0),$N$13:$N$65),7),"")} | J19: =IFERROR(I19/SUMIFS($N$13:$N$65,$M$13:$M$65,"Saída"),0) -> 0 | L19: =Categorias!A8 -> Custo de Serviços Prestados | M19: =Categorias!B8 -> Saída | N19: =SUMIFS(Lançamentos!$F:$F,Lançamentos!$H:$H,">="&$B$6,Lançamentos!$H:$H,"<="&$C$6,Lançamentos!$C:$C,L19,Lançamentos!$G:$G,IF($E$6="Todos","*",$E$6)) -> 0
B20: =IF(EDATE($B$6,7)<=$C$6,EDATE($B$6,7),"") -> 46235 | C20: =IF(B20="","",SUMIFS(Lançamentos!$F:$F,Lançamentos!$H:$H,B20,Lançamentos!$C:$C,IF($D$6="Todas","*",$D$6),Lançamentos!$G:$G,IF($E$6="Todos","*",$E$6),Lançamentos!$D:$D,"Entrada")) -> 0 | D20: =IF(B20="","",SUMIFS(Lançamentos!$F:$F,Lançamentos!$H:$H,B20,Lançamentos!$C:$C,IF($D$6="Todas","*",$D$6),Lançamentos!$G:$G,IF($E$6="Todos","*",$E$6),Lançamentos!$D:$D,"Saída")) -> 0 | E20: =IF(B20="","",C20+D20) -> 0 | F20: =IF(B20="","",F19+E20) -> 3166.79 | H20: =IFERROR(INDEX($L$13:$L$65,MATCH(I20,$N$13:$N$65,0)),"") | I20: {=IFERROR(SMALL(IF(($M$13:$M$65="Saída")*($N$13:$N$65<0),$N$13:$N$65),8),"")} | J20: =IFERROR(I20/SUMIFS($N$13:$N$65,$M$13:$M$65,"Saída"),0) -> 0 | L20: =Categorias!A9 -> Salários e Encargos | M20: =Categorias!B9 -> Saída | N20: =SUMIFS(Lançamentos!$F:$F,Lançamentos!$H:$H,">="&$B$6,Lançamentos!$H:$H,"<="&$C$6,Lançamentos!$C:$C,L20,Lançamentos!$G:$G,IF($E$6="Todos","*",$E$6)) -> 0
